[2025-05-01 01:04:15,995] 	INFO 	32 	id_data.py 	<module>() 	TC ID Data Started
[2025-05-01 01:04:16,225] 	ERROR 	104 	id_data.py 	<module>() 	Error occurred during TC ID Data process. Error: Dataframe is empty
Traceback (most recent call last):
  File "id_data.py", line 58, in <module>
    raise Exception('Dataframe is empty')
Exception: Dataframe is empty
[2025-05-01 02:55:06,958] 	INFO 	32 	id_data.py 	<module>() 	TC ID Data Started
[2025-05-01 02:55:07,315] 	ERROR 	104 	id_data.py 	<module>() 	Error occurred during TC ID Data process. Error: Dataframe is empty
Traceback (most recent call last):
  File "id_data.py", line 58, in <module>
    raise Exception('Dataframe is empty')
Exception: Dataframe is empty
[2025-05-01 03:41:32,937] 	INFO 	32 	id_data.py 	<module>() 	TC ID Data Started
[2025-05-01 03:41:33,249] 	ERROR 	104 	id_data.py 	<module>() 	Error occurred during TC ID Data process. Error: Dataframe is empty
Traceback (most recent call last):
  File "id_data.py", line 58, in <module>
    raise Exception('Dataframe is empty')
Exception: Dataframe is empty
[2025-05-01 04:02:19,772] 	INFO 	32 	id_data.py 	<module>() 	TC ID Data Started
[2025-05-01 04:02:20,130] 	ERROR 	104 	id_data.py 	<module>() 	Error occurred during TC ID Data process. Error: Dataframe is empty
Traceback (most recent call last):
  File "id_data.py", line 58, in <module>
    raise Exception('Dataframe is empty')
Exception: Dataframe is empty
[2025-05-01 04:36:46,166] 	INFO 	32 	id_data.py 	<module>() 	TC ID Data Started
[2025-05-01 04:36:46,482] 	ERROR 	104 	id_data.py 	<module>() 	Error occurred during TC ID Data process. Error: Dataframe is empty
Traceback (most recent call last):
  File "id_data.py", line 58, in <module>
    raise Exception('Dataframe is empty')
Exception: Dataframe is empty
[2025-05-01 04:52:08,663] 	INFO 	32 	id_data.py 	<module>() 	TC ID Data Started
[2025-05-01 04:52:09,023] 	ERROR 	104 	id_data.py 	<module>() 	Error occurred during TC ID Data process. Error: Dataframe is empty
Traceback (most recent call last):
  File "id_data.py", line 58, in <module>
    raise Exception('Dataframe is empty')
Exception: Dataframe is empty
[2025-05-01 05:13:10,431] 	INFO 	32 	id_data.py 	<module>() 	TC ID Data Started
[2025-05-01 05:13:10,704] 	ERROR 	104 	id_data.py 	<module>() 	Error occurred during TC ID Data process. Error: Dataframe is empty
Traceback (most recent call last):
  File "id_data.py", line 58, in <module>
    raise Exception('Dataframe is empty')
Exception: Dataframe is empty
[2025-05-01 05:33:13,130] 	INFO 	32 	id_data.py 	<module>() 	TC ID Data Started
[2025-05-01 05:33:13,470] 	ERROR 	104 	id_data.py 	<module>() 	Error occurred during TC ID Data process. Error: Dataframe is empty
Traceback (most recent call last):
  File "id_data.py", line 58, in <module>
    raise Exception('Dataframe is empty')
Exception: Dataframe is empty
[2025-05-01 05:47:59,893] 	INFO 	32 	id_data.py 	<module>() 	TC ID Data Started
[2025-05-01 05:48:00,166] 	ERROR 	104 	id_data.py 	<module>() 	Error occurred during TC ID Data process. Error: Dataframe is empty
Traceback (most recent call last):
  File "id_data.py", line 58, in <module>
    raise Exception('Dataframe is empty')
Exception: Dataframe is empty
[2025-05-01 06:18:21,349] 	INFO 	32 	id_data.py 	<module>() 	TC ID Data Started
[2025-05-01 06:18:21,618] 	ERROR 	104 	id_data.py 	<module>() 	Error occurred during TC ID Data process. Error: Dataframe is empty
Traceback (most recent call last):
  File "id_data.py", line 58, in <module>
    raise Exception('Dataframe is empty')
Exception: Dataframe is empty
