[2025-05-01 01:04:15,995] 	INFO 	32 	id_data.py 	<module>() 	TC ID Data Started
[2025-05-01 01:04:16,225] 	ERROR 	104 	id_data.py 	<module>() 	Error occurred during TC ID Data process. Error: Dataframe is empty
Traceback (most recent call last):
  File "id_data.py", line 58, in <module>
    raise Exception('Dataframe is empty')
Exception: Dataframe is empty
[2025-05-01 02:55:06,958] 	INFO 	32 	id_data.py 	<module>() 	TC ID Data Started
[2025-05-01 02:55:07,315] 	ERROR 	104 	id_data.py 	<module>() 	Error occurred during TC ID Data process. Error: Dataframe is empty
Traceback (most recent call last):
  File "id_data.py", line 58, in <module>
    raise Exception('Dataframe is empty')
Exception: Dataframe is empty
[2025-05-01 03:41:32,937] 	INFO 	32 	id_data.py 	<module>() 	TC ID Data Started
[2025-05-01 03:41:33,249] 	ERROR 	104 	id_data.py 	<module>() 	Error occurred during TC ID Data process. Error: Dataframe is empty
Traceback (most recent call last):
  File "id_data.py", line 58, in <module>
    raise Exception('Dataframe is empty')
Exception: Dataframe is empty
[2025-05-01 04:02:19,772] 	INFO 	32 	id_data.py 	<module>() 	TC ID Data Started
[2025-05-01 04:02:20,130] 	ERROR 	104 	id_data.py 	<module>() 	Error occurred during TC ID Data process. Error: Dataframe is empty
Traceback (most recent call last):
  File "id_data.py", line 58, in <module>
    raise Exception('Dataframe is empty')
Exception: Dataframe is empty
[2025-05-01 04:36:46,166] 	INFO 	32 	id_data.py 	<module>() 	TC ID Data Started
[2025-05-01 04:36:46,482] 	ERROR 	104 	id_data.py 	<module>() 	Error occurred during TC ID Data process. Error: Dataframe is empty
Traceback (most recent call last):
  File "id_data.py", line 58, in <module>
    raise Exception('Dataframe is empty')
Exception: Dataframe is empty
[2025-05-01 04:52:08,663] 	INFO 	32 	id_data.py 	<module>() 	TC ID Data Started
[2025-05-01 04:52:09,023] 	ERROR 	104 	id_data.py 	<module>() 	Error occurred during TC ID Data process. Error: Dataframe is empty
Traceback (most recent call last):
  File "id_data.py", line 58, in <module>
    raise Exception('Dataframe is empty')
Exception: Dataframe is empty
[2025-05-01 05:13:10,431] 	INFO 	32 	id_data.py 	<module>() 	TC ID Data Started
[2025-05-01 05:13:10,704] 	ERROR 	104 	id_data.py 	<module>() 	Error occurred during TC ID Data process. Error: Dataframe is empty
Traceback (most recent call last):
  File "id_data.py", line 58, in <module>
    raise Exception('Dataframe is empty')
Exception: Dataframe is empty
[2025-05-01 05:33:13,130] 	INFO 	32 	id_data.py 	<module>() 	TC ID Data Started
[2025-05-01 05:33:13,470] 	ERROR 	104 	id_data.py 	<module>() 	Error occurred during TC ID Data process. Error: Dataframe is empty
Traceback (most recent call last):
  File "id_data.py", line 58, in <module>
    raise Exception('Dataframe is empty')
Exception: Dataframe is empty
[2025-05-01 05:47:59,893] 	INFO 	32 	id_data.py 	<module>() 	TC ID Data Started
[2025-05-01 05:48:00,166] 	ERROR 	104 	id_data.py 	<module>() 	Error occurred during TC ID Data process. Error: Dataframe is empty
Traceback (most recent call last):
  File "id_data.py", line 58, in <module>
    raise Exception('Dataframe is empty')
Exception: Dataframe is empty
[2025-05-01 06:18:21,349] 	INFO 	32 	id_data.py 	<module>() 	TC ID Data Started
[2025-05-01 06:18:21,618] 	ERROR 	104 	id_data.py 	<module>() 	Error occurred during TC ID Data process. Error: Dataframe is empty
Traceback (most recent call last):
  File "id_data.py", line 58, in <module>
    raise Exception('Dataframe is empty')
Exception: Dataframe is empty
[2025-05-01 06:46:51,406] 	INFO 	32 	id_data.py 	<module>() 	TC ID Data Started
[2025-05-01 06:46:51,770] 	ERROR 	104 	id_data.py 	<module>() 	Error occurred during TC ID Data process. Error: Dataframe is empty
Traceback (most recent call last):
  File "id_data.py", line 58, in <module>
    raise Exception('Dataframe is empty')
Exception: Dataframe is empty
[2025-05-01 07:12:45,805] 	INFO 	32 	id_data.py 	<module>() 	TC ID Data Started
[2025-05-01 07:12:46,052] 	ERROR 	104 	id_data.py 	<module>() 	Error occurred during TC ID Data process. Error: Dataframe is empty
Traceback (most recent call last):
  File "id_data.py", line 58, in <module>
    raise Exception('Dataframe is empty')
Exception: Dataframe is empty
[2025-05-01 07:28:44,123] 	INFO 	32 	id_data.py 	<module>() 	TC ID Data Started
[2025-05-01 07:28:44,460] 	ERROR 	104 	id_data.py 	<module>() 	Error occurred during TC ID Data process. Error: Dataframe is empty
Traceback (most recent call last):
  File "id_data.py", line 58, in <module>
    raise Exception('Dataframe is empty')
Exception: Dataframe is empty
[2025-05-01 07:38:11,246] 	INFO 	32 	id_data.py 	<module>() 	TC ID Data Started
[2025-05-01 07:38:11,584] 	ERROR 	104 	id_data.py 	<module>() 	Error occurred during TC ID Data process. Error: Dataframe is empty
Traceback (most recent call last):
  File "id_data.py", line 58, in <module>
    raise Exception('Dataframe is empty')
Exception: Dataframe is empty
[2025-05-01 07:47:46,152] 	INFO 	32 	id_data.py 	<module>() 	TC ID Data Started
[2025-05-01 07:47:46,450] 	ERROR 	104 	id_data.py 	<module>() 	Error occurred during TC ID Data process. Error: Dataframe is empty
Traceback (most recent call last):
  File "id_data.py", line 58, in <module>
    raise Exception('Dataframe is empty')
Exception: Dataframe is empty
[2025-05-01 08:16:30,607] 	INFO 	32 	id_data.py 	<module>() 	TC ID Data Started
[2025-05-01 08:16:30,975] 	ERROR 	104 	id_data.py 	<module>() 	Error occurred during TC ID Data process. Error: Dataframe is empty
Traceback (most recent call last):
  File "id_data.py", line 58, in <module>
    raise Exception('Dataframe is empty')
Exception: Dataframe is empty
[2025-05-01 08:43:10,861] 	INFO 	32 	id_data.py 	<module>() 	TC ID Data Started
[2025-05-01 08:43:11,133] 	ERROR 	104 	id_data.py 	<module>() 	Error occurred during TC ID Data process. Error: Dataframe is empty
Traceback (most recent call last):
  File "id_data.py", line 58, in <module>
    raise Exception('Dataframe is empty')
Exception: Dataframe is empty
[2025-05-01 08:54:27,031] 	INFO 	32 	id_data.py 	<module>() 	TC ID Data Started
[2025-05-01 08:54:27,274] 	ERROR 	104 	id_data.py 	<module>() 	Error occurred during TC ID Data process. Error: Dataframe is empty
Traceback (most recent call last):
  File "id_data.py", line 58, in <module>
    raise Exception('Dataframe is empty')
Exception: Dataframe is empty
[2025-05-01 09:13:09,063] 	INFO 	32 	id_data.py 	<module>() 	TC ID Data Started
[2025-05-01 09:13:09,422] 	ERROR 	104 	id_data.py 	<module>() 	Error occurred during TC ID Data process. Error: Dataframe is empty
Traceback (most recent call last):
  File "id_data.py", line 58, in <module>
    raise Exception('Dataframe is empty')
Exception: Dataframe is empty
[2025-05-01 09:31:18,014] 	INFO 	32 	id_data.py 	<module>() 	TC ID Data Started
[2025-05-01 09:31:18,373] 	ERROR 	104 	id_data.py 	<module>() 	Error occurred during TC ID Data process. Error: Dataframe is empty
Traceback (most recent call last):
  File "id_data.py", line 58, in <module>
    raise Exception('Dataframe is empty')
Exception: Dataframe is empty
[2025-05-01 09:47:39,100] 	INFO 	32 	id_data.py 	<module>() 	TC ID Data Started
[2025-05-01 09:47:39,320] 	ERROR 	104 	id_data.py 	<module>() 	Error occurred during TC ID Data process. Error: Dataframe is empty
Traceback (most recent call last):
  File "id_data.py", line 58, in <module>
    raise Exception('Dataframe is empty')
Exception: Dataframe is empty
[2025-05-01 10:12:46,097] 	INFO 	32 	id_data.py 	<module>() 	TC ID Data Started
[2025-05-01 10:12:46,297] 	ERROR 	104 	id_data.py 	<module>() 	Error occurred during TC ID Data process. Error: Dataframe is empty
Traceback (most recent call last):
  File "id_data.py", line 58, in <module>
    raise Exception('Dataframe is empty')
Exception: Dataframe is empty
[2025-05-01 10:35:52,640] 	INFO 	32 	id_data.py 	<module>() 	TC ID Data Started
[2025-05-01 10:35:52,907] 	ERROR 	104 	id_data.py 	<module>() 	Error occurred during TC ID Data process. Error: Dataframe is empty
Traceback (most recent call last):
  File "id_data.py", line 58, in <module>
    raise Exception('Dataframe is empty')
Exception: Dataframe is empty
[2025-05-01 10:50:12,978] 	INFO 	32 	id_data.py 	<module>() 	TC ID Data Started
[2025-05-01 10:50:13,347] 	ERROR 	104 	id_data.py 	<module>() 	Error occurred during TC ID Data process. Error: Dataframe is empty
Traceback (most recent call last):
  File "id_data.py", line 58, in <module>
    raise Exception('Dataframe is empty')
Exception: Dataframe is empty
